[2025-07-29 03:07:43] 종합 투자 상태 조회 오류: HTTPSConnectionPool(host='api.upbit.com', port=443): Max retries exceeded with url: /v1/accounts (Caused by NameResolutionError("<urllib3.connection.HTTPSConnection object at 0x000001BDB5059EB0>: Failed to resolve 'api.upbit.com' ([Errno 11001] getaddrinfo failed)"))
Traceback (most recent call last):
  File "C:\Users\zcb16\AppData\Roaming\Python\Python312\site-packages\urllib3\connection.py", line 198, in _new_conn
    sock = connection.create_connection(
           ^^^^^^^^^^^^^^^^^^^^^^^^^^^^^
  File "C:\Users\zcb16\AppData\Roaming\Python\Python312\site-packages\urllib3\util\connection.py", line 60, in create_connection
    for res in socket.getaddrinfo(host, port, family, socket.SOCK_STREAM):
               ^^^^^^^^^^^^^^^^^^^^^^^^^^^^^^^^^^^^^^^^^^^^^^^^^^^^^^^^^^
  File "C:\Python312\Lib\socket.py", line 976, in getaddrinfo
    for res in _socket.getaddrinfo(host, port, family, type, proto, flags):
               ^^^^^^^^^^^^^^^^^^^^^^^^^^^^^^^^^^^^^^^^^^^^^^^^^^^^^^^^^^^
socket.gaierror: [Errno 11001] getaddrinfo failed

The above exception was the direct cause of the following exception:

Traceback (most recent call last):
  File "C:\Users\zcb16\AppData\Roaming\Python\Python312\site-packages\urllib3\connectionpool.py", line 787, in urlopen
    response = self._make_request(
               ^^^^^^^^^^^^^^^^^^^
  File "C:\Users\zcb16\AppData\Roaming\Python\Python312\site-packages\urllib3\connectionpool.py", line 488, in _make_request
    raise new_e
  File "C:\Users\zcb16\AppData\Roaming\Python\Python312\site-packages\urllib3\connectionpool.py", line 464, in _make_request
    self._validate_conn(conn)
  File "C:\Users\zcb16\AppData\Roaming\Python\Python312\site-packages\urllib3\connectionpool.py", line 1093, in _validate_conn
    conn.connect()
  File "C:\Users\zcb16\AppData\Roaming\Python\Python312\site-packages\urllib3\connection.py", line 753, in connect
    self.sock = sock = self._new_conn()
                       ^^^^^^^^^^^^^^^^
  File "C:\Users\zcb16\AppData\Roaming\Python\Python312\site-packages\urllib3\connection.py", line 205, in _new_conn
    raise NameResolutionError(self.host, self, e) from e
urllib3.exceptions.NameResolutionError: <urllib3.connection.HTTPSConnection object at 0x000001BDB5059EB0>: Failed to resolve 'api.upbit.com' ([Errno 11001] getaddrinfo failed)

The above exception was the direct cause of the following exception:

Traceback (most recent call last):
  File "C:\Users\zcb16\AppData\Roaming\Python\Python312\site-packages\requests\adapters.py", line 667, in send
    resp = conn.urlopen(
           ^^^^^^^^^^^^^
  File "C:\Users\zcb16\AppData\Roaming\Python\Python312\site-packages\urllib3\connectionpool.py", line 841, in urlopen
    retries = retries.increment(
              ^^^^^^^^^^^^^^^^^^
  File "C:\Users\zcb16\AppData\Roaming\Python\Python312\site-packages\urllib3\util\retry.py", line 519, in increment
    raise MaxRetryError(_pool, url, reason) from reason  # type: ignore[arg-type]
    ^^^^^^^^^^^^^^^^^^^^^^^^^^^^^^^^^^^^^^^^^^^^^^^^^^^
urllib3.exceptions.MaxRetryError: HTTPSConnectionPool(host='api.upbit.com', port=443): Max retries exceeded with url: /v1/accounts (Caused by NameResolutionError("<urllib3.connection.HTTPSConnection object at 0x000001BDB5059EB0>: Failed to resolve 'api.upbit.com' ([Errno 11001] getaddrinfo failed)"))

During handling of the above exception, another exception occurred:

Traceback (most recent call last):
  File "C:\Coding\AutoTrading\trading\portfolio.py", line 72, in get_comprehensive_investment_status
    break
       ^^^
  File "C:\Users\zcb16\AppData\Roaming\Python\Python312\site-packages\pyupbit\exchange_api.py", line 109, in get_balances
    result = _send_get_request(url, headers=headers)
             ^^^^^^^^^^^^^^^^^^^^^^^^^^^^^^^^^^^^^^^
  File "C:\Users\zcb16\AppData\Roaming\Python\Python312\site-packages\pyupbit\request_api.py", line 107, in _send_get_request
    resp = _call_get(url, headers=headers, data=data)
           ^^^^^^^^^^^^^^^^^^^^^^^^^^^^^^^^^^^^^^^^^^
  File "C:\Users\zcb16\AppData\Roaming\Python\Python312\site-packages\pyupbit\errors.py", line 165, in wrapper
    resp = func(*args, **kwargs)
           ^^^^^^^^^^^^^^^^^^^^^
  File "C:\Users\zcb16\AppData\Roaming\Python\Python312\site-packages\pyupbit\request_api.py", line 42, in _call_get
    return requests.get(url, **kwargs)
           ^^^^^^^^^^^^^^^^^^^^^^^^^^^
  File "C:\Users\zcb16\AppData\Roaming\Python\Python312\site-packages\requests\api.py", line 73, in get
    return request("get", url, params=params, **kwargs)
           ^^^^^^^^^^^^^^^^^^^^^^^^^^^^^^^^^^^^^^^^^^^^
  File "C:\Users\zcb16\AppData\Roaming\Python\Python312\site-packages\requests\api.py", line 59, in request
    return session.request(method=method, url=url, **kwargs)
           ^^^^^^^^^^^^^^^^^^^^^^^^^^^^^^^^^^^^^^^^^^^^^^^^^
  File "C:\Users\zcb16\AppData\Roaming\Python\Python312\site-packages\requests\sessions.py", line 589, in request
    resp = self.send(prep, **send_kwargs)
           ^^^^^^^^^^^^^^^^^^^^^^^^^^^^^^
  File "C:\Users\zcb16\AppData\Roaming\Python\Python312\site-packages\requests\sessions.py", line 703, in send
    r = adapter.send(request, **kwargs)
        ^^^^^^^^^^^^^^^^^^^^^^^^^^^^^^^
  File "C:\Users\zcb16\AppData\Roaming\Python\Python312\site-packages\requests\adapters.py", line 700, in send
    raise ConnectionError(e, request=request)
requests.exceptions.ConnectionError: HTTPSConnectionPool(host='api.upbit.com', port=443): Max retries exceeded with url: /v1/accounts (Caused by NameResolutionError("<urllib3.connection.HTTPSConnection object at 0x000001BDB5059EB0>: Failed to resolve 'api.upbit.com' ([Errno 11001] getaddrinfo failed)"))

[2025-07-29 10:38:24] 종합 투자 상태 조회 오류: HTTPSConnectionPool(host='api.upbit.com', port=443): Max retries exceeded with url: /v1/accounts (Caused by NameResolutionError("<urllib3.connection.HTTPSConnection object at 0x000001BDB505B1D0>: Failed to resolve 'api.upbit.com' ([Errno 11001] getaddrinfo failed)"))
Traceback (most recent call last):
  File "C:\Users\zcb16\AppData\Roaming\Python\Python312\site-packages\urllib3\connection.py", line 198, in _new_conn
    sock = connection.create_connection(
           ^^^^^^^^^^^^^^^^^^^^^^^^^^^^^
  File "C:\Users\zcb16\AppData\Roaming\Python\Python312\site-packages\urllib3\util\connection.py", line 60, in create_connection
    for res in socket.getaddrinfo(host, port, family, socket.SOCK_STREAM):
               ^^^^^^^^^^^^^^^^^^^^^^^^^^^^^^^^^^^^^^^^^^^^^^^^^^^^^^^^^^
  File "C:\Python312\Lib\socket.py", line 976, in getaddrinfo
    for res in _socket.getaddrinfo(host, port, family, type, proto, flags):
               ^^^^^^^^^^^^^^^^^^^^^^^^^^^^^^^^^^^^^^^^^^^^^^^^^^^^^^^^^^^
socket.gaierror: [Errno 11001] getaddrinfo failed

The above exception was the direct cause of the following exception:

Traceback (most recent call last):
  File "C:\Users\zcb16\AppData\Roaming\Python\Python312\site-packages\urllib3\connectionpool.py", line 787, in urlopen
    response = self._make_request(
               ^^^^^^^^^^^^^^^^^^^
  File "C:\Users\zcb16\AppData\Roaming\Python\Python312\site-packages\urllib3\connectionpool.py", line 488, in _make_request
    raise new_e
  File "C:\Users\zcb16\AppData\Roaming\Python\Python312\site-packages\urllib3\connectionpool.py", line 464, in _make_request
    self._validate_conn(conn)
  File "C:\Users\zcb16\AppData\Roaming\Python\Python312\site-packages\urllib3\connectionpool.py", line 1093, in _validate_conn
    conn.connect()
  File "C:\Users\zcb16\AppData\Roaming\Python\Python312\site-packages\urllib3\connection.py", line 753, in connect
    self.sock = sock = self._new_conn()
                       ^^^^^^^^^^^^^^^^
  File "C:\Users\zcb16\AppData\Roaming\Python\Python312\site-packages\urllib3\connection.py", line 205, in _new_conn
    raise NameResolutionError(self.host, self, e) from e
urllib3.exceptions.NameResolutionError: <urllib3.connection.HTTPSConnection object at 0x000001BDB505B1D0>: Failed to resolve 'api.upbit.com' ([Errno 11001] getaddrinfo failed)

The above exception was the direct cause of the following exception:

Traceback (most recent call last):
  File "C:\Users\zcb16\AppData\Roaming\Python\Python312\site-packages\requests\adapters.py", line 667, in send
    resp = conn.urlopen(
           ^^^^^^^^^^^^^
  File "C:\Users\zcb16\AppData\Roaming\Python\Python312\site-packages\urllib3\connectionpool.py", line 841, in urlopen
    retries = retries.increment(
              ^^^^^^^^^^^^^^^^^^
  File "C:\Users\zcb16\AppData\Roaming\Python\Python312\site-packages\urllib3\util\retry.py", line 519, in increment
    raise MaxRetryError(_pool, url, reason) from reason  # type: ignore[arg-type]
    ^^^^^^^^^^^^^^^^^^^^^^^^^^^^^^^^^^^^^^^^^^^^^^^^^^^
urllib3.exceptions.MaxRetryError: HTTPSConnectionPool(host='api.upbit.com', port=443): Max retries exceeded with url: /v1/accounts (Caused by NameResolutionError("<urllib3.connection.HTTPSConnection object at 0x000001BDB505B1D0>: Failed to resolve 'api.upbit.com' ([Errno 11001] getaddrinfo failed)"))

During handling of the above exception, another exception occurred:

Traceback (most recent call last):
  File "C:\Coding\AutoTrading\trading\portfolio.py", line 72, in get_comprehensive_investment_status
    break
       ^^^
  File "C:\Users\zcb16\AppData\Roaming\Python\Python312\site-packages\pyupbit\exchange_api.py", line 109, in get_balances
    result = _send_get_request(url, headers=headers)
             ^^^^^^^^^^^^^^^^^^^^^^^^^^^^^^^^^^^^^^^
  File "C:\Users\zcb16\AppData\Roaming\Python\Python312\site-packages\pyupbit\request_api.py", line 107, in _send_get_request
    resp = _call_get(url, headers=headers, data=data)
           ^^^^^^^^^^^^^^^^^^^^^^^^^^^^^^^^^^^^^^^^^^
  File "C:\Users\zcb16\AppData\Roaming\Python\Python312\site-packages\pyupbit\errors.py", line 165, in wrapper
    resp = func(*args, **kwargs)
           ^^^^^^^^^^^^^^^^^^^^^
  File "C:\Users\zcb16\AppData\Roaming\Python\Python312\site-packages\pyupbit\request_api.py", line 42, in _call_get
    return requests.get(url, **kwargs)
           ^^^^^^^^^^^^^^^^^^^^^^^^^^^
  File "C:\Users\zcb16\AppData\Roaming\Python\Python312\site-packages\requests\api.py", line 73, in get
    return request("get", url, params=params, **kwargs)
           ^^^^^^^^^^^^^^^^^^^^^^^^^^^^^^^^^^^^^^^^^^^^
  File "C:\Users\zcb16\AppData\Roaming\Python\Python312\site-packages\requests\api.py", line 59, in request
    return session.request(method=method, url=url, **kwargs)
           ^^^^^^^^^^^^^^^^^^^^^^^^^^^^^^^^^^^^^^^^^^^^^^^^^
  File "C:\Users\zcb16\AppData\Roaming\Python\Python312\site-packages\requests\sessions.py", line 589, in request
    resp = self.send(prep, **send_kwargs)
           ^^^^^^^^^^^^^^^^^^^^^^^^^^^^^^
  File "C:\Users\zcb16\AppData\Roaming\Python\Python312\site-packages\requests\sessions.py", line 703, in send
    r = adapter.send(request, **kwargs)
        ^^^^^^^^^^^^^^^^^^^^^^^^^^^^^^^
  File "C:\Users\zcb16\AppData\Roaming\Python\Python312\site-packages\requests\adapters.py", line 700, in send
    raise ConnectionError(e, request=request)
requests.exceptions.ConnectionError: HTTPSConnectionPool(host='api.upbit.com', port=443): Max retries exceeded with url: /v1/accounts (Caused by NameResolutionError("<urllib3.connection.HTTPSConnection object at 0x000001BDB505B1D0>: Failed to resolve 'api.upbit.com' ([Errno 11001] getaddrinfo failed)"))

[2025-07-29 10:49:14] [DEBUG] Fetched balances: {'error': {'message': 'This is not a verified IP.', 'name': 'no_authorization_ip'}}
[2025-07-29 10:49:14] 종합 투자 상태 조회 오류: string indices must be integers, not 'str'
Traceback (most recent call last):
  File "C:\Coding\AutoTrading\trading\portfolio.py", line 80, in get_comprehensive_investment_status
    def _log_balances_summary(self, balances, target_coin):
                   ^^^^^^^^^^^^^^^^^^^
TypeError: string indices must be integers, not 'str'

[2025-07-29 10:49:47] [DEBUG] Fetched balances: {'error': {'message': 'This is not a verified IP.', 'name': 'no_authorization_ip'}}
[2025-07-29 10:49:47] 종합 투자 상태 조회 오류: string indices must be integers, not 'str'
Traceback (most recent call last):
  File "C:\Coding\AutoTrading\trading\portfolio.py", line 80, in get_comprehensive_investment_status
    def _log_balances_summary(self, balances, target_coin):
                   ^^^^^^^^^^^^^^^^^^^
TypeError: string indices must be integers, not 'str'

[2025-07-29 10:50:17] [DEBUG] Fetched balances: {'error': {'message': 'This is not a verified IP.', 'name': 'no_authorization_ip'}}
[2025-07-29 10:50:17] 종합 투자 상태 조회 오류: string indices must be integers, not 'str'
Traceback (most recent call last):
  File "C:\Coding\AutoTrading\trading\portfolio.py", line 80, in get_comprehensive_investment_status
    def _log_balances_summary(self, balances, target_coin):
                   ^^^^^^^^^^^^^^^^^^^
TypeError: string indices must be integers, not 'str'

[2025-07-29 10:50:47] [DEBUG] Fetched balances: {'error': {'message': 'This is not a verified IP.', 'name': 'no_authorization_ip'}}
[2025-07-29 10:50:47] 종합 투자 상태 조회 오류: string indices must be integers, not 'str'
Traceback (most recent call last):
  File "C:\Coding\AutoTrading\trading\portfolio.py", line 80, in get_comprehensive_investment_status
    def _log_balances_summary(self, balances, target_coin):
                   ^^^^^^^^^^^^^^^^^^^
TypeError: string indices must be integers, not 'str'

