[2025-07-28 03:17:12] [DEBUG] Fetched balances: [{'currency': 'BTC', 'balance': '0.00019892', 'locked': '0', 'avg_buy_price': '160866000', 'avg_buy_price_modified': False, 'unit_currency': 'KRW'}, {'currency': 'KRW', 'balance': '33340.0054458', 'locked': '0', 'avg_buy_price': '0', 'avg_buy_price_modified': True, 'unit_currency': 'KRW'}, {'currency': 'ETH', 'balance': '0.005', 'locked': '0', 'avg_buy_price': '5237000', 'avg_buy_price_modified': False, 'unit_currency': 'KRW'}, {'currency': 'SOL', 'balance': '0.03251821', 'locked': '0', 'avg_buy_price': '256350', 'avg_buy_price_modified': False, 'unit_currency': 'KRW'}]
[2025-07-28 03:17:12] [DEBUG] KRW Balance: 33340.0054458
[2025-07-28 03:17:12] [DEBUG] Processing KRW-BTC: Balance=0.00019892, Avg Buy Price=160866000.0
[2025-07-28 03:17:12] [DEBUG] Current price for KRW-BTC (attempt 1): 162474000.0
[2025-07-28 03:17:12] [DEBUG] Processing KRW-ETH: Balance=0.005, Avg Buy Price=5237000.0
[2025-07-28 03:17:12] [WARNING] Failed to get current price for KRW-ETH (attempt 1): 0
[2025-07-28 03:17:13] [DEBUG] Current price for KRW-ETH (attempt 2): 5237000.0
[2025-07-28 03:17:13] [DEBUG] Processing KRW-XRP: Balance=0, Avg Buy Price=0
[2025-07-28 03:17:13] [DEBUG] No balance for KRW-XRP. Skipping.
[2025-07-28 03:17:13] [DEBUG] Processing KRW-ADA: Balance=0, Avg Buy Price=0
[2025-07-28 03:17:13] [DEBUG] No balance for KRW-ADA. Skipping.
[2025-07-28 03:17:13] [DEBUG] Processing KRW-SOL: Balance=0.03251821, Avg Buy Price=256350.0
[2025-07-28 03:17:13] [DEBUG] Current price for KRW-SOL (attempt 1): 256000.0
[2025-07-28 03:17:13] [DEBUG] Processing KRW-DOGE: Balance=0, Avg Buy Price=0
[2025-07-28 03:17:13] [DEBUG] No balance for KRW-DOGE. Skipping.
[2025-07-28 03:17:13] [DEBUG] Processing KRW-AVAX: Balance=0, Avg Buy Price=0
[2025-07-28 03:17:13] [DEBUG] No balance for KRW-AVAX. Skipping.
[2025-07-28 03:17:13] [DEBUG] Processing KRW-DOT: Balance=0, Avg Buy Price=0
[2025-07-28 03:17:13] [DEBUG] No balance for KRW-DOT. Skipping.
[2025-07-28 03:17:13] [DEBUG] Processing KRW-MATIC: Balance=0, Avg Buy Price=0
[2025-07-28 03:17:13] [DEBUG] No balance for KRW-MATIC. Skipping.
[2025-07-28 03:17:13] [DEBUG] Processing KRW-LINK: Balance=0, Avg Buy Price=0
[2025-07-28 03:17:13] [DEBUG] No balance for KRW-LINK. Skipping.
[2025-07-28 03:17:13] [DEBUG] Processing KRW-UNI: Balance=0, Avg Buy Price=0
[2025-07-28 03:17:13] [DEBUG] No balance for KRW-UNI. Skipping.
[2025-07-28 03:17:13] [DEBUG] Processing KRW-LTC: Balance=0, Avg Buy Price=0
[2025-07-28 03:17:13] [DEBUG] No balance for KRW-LTC. Skipping.
[2025-07-28 03:17:13] [DEBUG] Processing KRW-BCH: Balance=0, Avg Buy Price=0
[2025-07-28 03:17:13] [DEBUG] No balance for KRW-BCH. Skipping.
[2025-07-28 03:17:13] [DEBUG] Processing KRW-ATOM: Balance=0, Avg Buy Price=0
[2025-07-28 03:17:13] [DEBUG] No balance for KRW-ATOM. Skipping.
[2025-07-28 03:17:13] [DEBUG] Processing KRW-NEAR: Balance=0, Avg Buy Price=0
[2025-07-28 03:17:13] [DEBUG] No balance for KRW-NEAR. Skipping.
[2025-07-28 03:17:29] [DEBUG] Fetched balances: [{'currency': 'BTC', 'balance': '0.00019892', 'locked': '0', 'avg_buy_price': '160866000', 'avg_buy_price_modified': False, 'unit_currency': 'KRW'}, {'currency': 'KRW', 'balance': '33340.0054458', 'locked': '0', 'avg_buy_price': '0', 'avg_buy_price_modified': True, 'unit_currency': 'KRW'}, {'currency': 'ETH', 'balance': '0.005', 'locked': '0', 'avg_buy_price': '5237000', 'avg_buy_price_modified': False, 'unit_currency': 'KRW'}, {'currency': 'SOL', 'balance': '0.03251821', 'locked': '0', 'avg_buy_price': '256350', 'avg_buy_price_modified': False, 'unit_currency': 'KRW'}]
[2025-07-28 03:17:29] [DEBUG] KRW Balance: 33340.0054458
[2025-07-28 03:17:29] [DEBUG] Processing KRW-BTC: Balance=0.00019892, Avg Buy Price=160866000.0
[2025-07-28 03:17:29] [WARNING] Failed to get current price for KRW-BTC: 0. Skipping this coin.
[2025-07-28 03:17:29] [WARNING] Current price for KRW-BTC is invalid (None). Skipping this coin.
[2025-07-28 03:17:29] [DEBUG] Processing KRW-ETH: Balance=0.005, Avg Buy Price=5237000.0
[2025-07-28 03:17:29] [WARNING] Failed to get current price for KRW-ETH: 0. Skipping this coin.
[2025-07-28 03:17:29] [WARNING] Current price for KRW-ETH is invalid (None). Skipping this coin.
[2025-07-28 03:17:29] [DEBUG] Processing KRW-XRP: Balance=0, Avg Buy Price=0
[2025-07-28 03:17:29] [DEBUG] No balance for KRW-XRP. Skipping.
[2025-07-28 03:17:29] [DEBUG] Processing KRW-ADA: Balance=0, Avg Buy Price=0
[2025-07-28 03:17:29] [DEBUG] No balance for KRW-ADA. Skipping.
[2025-07-28 03:17:29] [DEBUG] Processing KRW-SOL: Balance=0.03251821, Avg Buy Price=256350.0
[2025-07-28 03:17:30] [WARNING] Failed to get current price for KRW-SOL: 0. Skipping this coin.
[2025-07-28 03:17:30] [WARNING] Current price for KRW-SOL is invalid (None). Skipping this coin.
[2025-07-28 03:17:30] [DEBUG] Processing KRW-DOGE: Balance=0, Avg Buy Price=0
[2025-07-28 03:17:30] [DEBUG] No balance for KRW-DOGE. Skipping.
[2025-07-28 03:17:30] [DEBUG] Processing KRW-AVAX: Balance=0, Avg Buy Price=0
[2025-07-28 03:17:30] [DEBUG] No balance for KRW-AVAX. Skipping.
[2025-07-28 03:17:30] [DEBUG] Processing KRW-DOT: Balance=0, Avg Buy Price=0
[2025-07-28 03:17:30] [DEBUG] No balance for KRW-DOT. Skipping.
[2025-07-28 03:17:30] [DEBUG] Processing KRW-MATIC: Balance=0, Avg Buy Price=0
[2025-07-28 03:17:30] [DEBUG] No balance for KRW-MATIC. Skipping.
[2025-07-28 03:17:30] [DEBUG] Processing KRW-LINK: Balance=0, Avg Buy Price=0
[2025-07-28 03:17:30] [DEBUG] No balance for KRW-LINK. Skipping.
[2025-07-28 03:17:30] [DEBUG] Processing KRW-UNI: Balance=0, Avg Buy Price=0
[2025-07-28 03:17:30] [DEBUG] No balance for KRW-UNI. Skipping.
[2025-07-28 03:17:30] [DEBUG] Processing KRW-LTC: Balance=0, Avg Buy Price=0
[2025-07-28 03:17:30] [DEBUG] No balance for KRW-LTC. Skipping.
[2025-07-28 03:17:30] [DEBUG] Processing KRW-BCH: Balance=0, Avg Buy Price=0
[2025-07-28 03:17:30] [DEBUG] No balance for KRW-BCH. Skipping.
[2025-07-28 03:17:30] [DEBUG] Processing KRW-ATOM: Balance=0, Avg Buy Price=0
[2025-07-28 03:17:30] [DEBUG] No balance for KRW-ATOM. Skipping.
[2025-07-28 03:17:30] [DEBUG] Processing KRW-NEAR: Balance=0, Avg Buy Price=0
[2025-07-28 03:17:30] [DEBUG] No balance for KRW-NEAR. Skipping.
[2025-07-28 04:35:40] 종합 투자 상태 조회 오류: HTTPSConnectionPool(host='api.upbit.com', port=443): Max retries exceeded with url: /v1/accounts (Caused by NameResolutionError("<urllib3.connection.HTTPSConnection object at 0x000001BDB50CA270>: Failed to resolve 'api.upbit.com' ([Errno 11001] getaddrinfo failed)"))
Traceback (most recent call last):
  File "C:\Users\zcb16\AppData\Roaming\Python\Python312\site-packages\urllib3\connection.py", line 198, in _new_conn
    sock = connection.create_connection(
           ^^^^^^^^^^^^^^^^^^^^^^^^^^^^^
  File "C:\Users\zcb16\AppData\Roaming\Python\Python312\site-packages\urllib3\util\connection.py", line 60, in create_connection
    for res in socket.getaddrinfo(host, port, family, socket.SOCK_STREAM):
               ^^^^^^^^^^^^^^^^^^^^^^^^^^^^^^^^^^^^^^^^^^^^^^^^^^^^^^^^^^
  File "C:\Python312\Lib\socket.py", line 976, in getaddrinfo
    for res in _socket.getaddrinfo(host, port, family, type, proto, flags):
               ^^^^^^^^^^^^^^^^^^^^^^^^^^^^^^^^^^^^^^^^^^^^^^^^^^^^^^^^^^^
socket.gaierror: [Errno 11001] getaddrinfo failed

The above exception was the direct cause of the following exception:

Traceback (most recent call last):
  File "C:\Users\zcb16\AppData\Roaming\Python\Python312\site-packages\urllib3\connectionpool.py", line 787, in urlopen
    response = self._make_request(
               ^^^^^^^^^^^^^^^^^^^
  File "C:\Users\zcb16\AppData\Roaming\Python\Python312\site-packages\urllib3\connectionpool.py", line 488, in _make_request
    raise new_e
  File "C:\Users\zcb16\AppData\Roaming\Python\Python312\site-packages\urllib3\connectionpool.py", line 464, in _make_request
    self._validate_conn(conn)
  File "C:\Users\zcb16\AppData\Roaming\Python\Python312\site-packages\urllib3\connectionpool.py", line 1093, in _validate_conn
    conn.connect()
  File "C:\Users\zcb16\AppData\Roaming\Python\Python312\site-packages\urllib3\connection.py", line 753, in connect
    self.sock = sock = self._new_conn()
                       ^^^^^^^^^^^^^^^^
  File "C:\Users\zcb16\AppData\Roaming\Python\Python312\site-packages\urllib3\connection.py", line 205, in _new_conn
    raise NameResolutionError(self.host, self, e) from e
urllib3.exceptions.NameResolutionError: <urllib3.connection.HTTPSConnection object at 0x000001BDB50CA270>: Failed to resolve 'api.upbit.com' ([Errno 11001] getaddrinfo failed)

The above exception was the direct cause of the following exception:

Traceback (most recent call last):
  File "C:\Users\zcb16\AppData\Roaming\Python\Python312\site-packages\requests\adapters.py", line 667, in send
    resp = conn.urlopen(
           ^^^^^^^^^^^^^
  File "C:\Users\zcb16\AppData\Roaming\Python\Python312\site-packages\urllib3\connectionpool.py", line 841, in urlopen
    retries = retries.increment(
              ^^^^^^^^^^^^^^^^^^
  File "C:\Users\zcb16\AppData\Roaming\Python\Python312\site-packages\urllib3\util\retry.py", line 519, in increment
    raise MaxRetryError(_pool, url, reason) from reason  # type: ignore[arg-type]
    ^^^^^^^^^^^^^^^^^^^^^^^^^^^^^^^^^^^^^^^^^^^^^^^^^^^
urllib3.exceptions.MaxRetryError: HTTPSConnectionPool(host='api.upbit.com', port=443): Max retries exceeded with url: /v1/accounts (Caused by NameResolutionError("<urllib3.connection.HTTPSConnection object at 0x000001BDB50CA270>: Failed to resolve 'api.upbit.com' ([Errno 11001] getaddrinfo failed)"))

During handling of the above exception, another exception occurred:

Traceback (most recent call last):
  File "C:\Coding\AutoTrading\trading\portfolio.py", line 72, in get_comprehensive_investment_status
    break
       ^^^
  File "C:\Users\zcb16\AppData\Roaming\Python\Python312\site-packages\pyupbit\exchange_api.py", line 109, in get_balances
    result = _send_get_request(url, headers=headers)
             ^^^^^^^^^^^^^^^^^^^^^^^^^^^^^^^^^^^^^^^
  File "C:\Users\zcb16\AppData\Roaming\Python\Python312\site-packages\pyupbit\request_api.py", line 107, in _send_get_request
    resp = _call_get(url, headers=headers, data=data)
           ^^^^^^^^^^^^^^^^^^^^^^^^^^^^^^^^^^^^^^^^^^
  File "C:\Users\zcb16\AppData\Roaming\Python\Python312\site-packages\pyupbit\errors.py", line 165, in wrapper
    resp = func(*args, **kwargs)
           ^^^^^^^^^^^^^^^^^^^^^
  File "C:\Users\zcb16\AppData\Roaming\Python\Python312\site-packages\pyupbit\request_api.py", line 42, in _call_get
    return requests.get(url, **kwargs)
           ^^^^^^^^^^^^^^^^^^^^^^^^^^^
  File "C:\Users\zcb16\AppData\Roaming\Python\Python312\site-packages\requests\api.py", line 73, in get
    return request("get", url, params=params, **kwargs)
           ^^^^^^^^^^^^^^^^^^^^^^^^^^^^^^^^^^^^^^^^^^^^
  File "C:\Users\zcb16\AppData\Roaming\Python\Python312\site-packages\requests\api.py", line 59, in request
    return session.request(method=method, url=url, **kwargs)
           ^^^^^^^^^^^^^^^^^^^^^^^^^^^^^^^^^^^^^^^^^^^^^^^^^
  File "C:\Users\zcb16\AppData\Roaming\Python\Python312\site-packages\requests\sessions.py", line 589, in request
    resp = self.send(prep, **send_kwargs)
           ^^^^^^^^^^^^^^^^^^^^^^^^^^^^^^
  File "C:\Users\zcb16\AppData\Roaming\Python\Python312\site-packages\requests\sessions.py", line 703, in send
    r = adapter.send(request, **kwargs)
        ^^^^^^^^^^^^^^^^^^^^^^^^^^^^^^^
  File "C:\Users\zcb16\AppData\Roaming\Python\Python312\site-packages\requests\adapters.py", line 700, in send
    raise ConnectionError(e, request=request)
requests.exceptions.ConnectionError: HTTPSConnectionPool(host='api.upbit.com', port=443): Max retries exceeded with url: /v1/accounts (Caused by NameResolutionError("<urllib3.connection.HTTPSConnection object at 0x000001BDB50CA270>: Failed to resolve 'api.upbit.com' ([Errno 11001] getaddrinfo failed)"))

[2025-07-28 04:35:40] Failed to get comprehensive investment status.
[2025-07-28 04:35:40] [DEBUG] Investment status was None or empty.
[2025-07-28 04:36:10] 종합 투자 상태 조회 오류: HTTPSConnectionPool(host='api.upbit.com', port=443): Max retries exceeded with url: /v1/accounts (Caused by NameResolutionError("<urllib3.connection.HTTPSConnection object at 0x000001BDB50E5340>: Failed to resolve 'api.upbit.com' ([Errno 11001] getaddrinfo failed)"))
Traceback (most recent call last):
  File "C:\Users\zcb16\AppData\Roaming\Python\Python312\site-packages\urllib3\connection.py", line 198, in _new_conn
    sock = connection.create_connection(
           ^^^^^^^^^^^^^^^^^^^^^^^^^^^^^
  File "C:\Users\zcb16\AppData\Roaming\Python\Python312\site-packages\urllib3\util\connection.py", line 60, in create_connection
    for res in socket.getaddrinfo(host, port, family, socket.SOCK_STREAM):
               ^^^^^^^^^^^^^^^^^^^^^^^^^^^^^^^^^^^^^^^^^^^^^^^^^^^^^^^^^^
  File "C:\Python312\Lib\socket.py", line 976, in getaddrinfo
    for res in _socket.getaddrinfo(host, port, family, type, proto, flags):
               ^^^^^^^^^^^^^^^^^^^^^^^^^^^^^^^^^^^^^^^^^^^^^^^^^^^^^^^^^^^
socket.gaierror: [Errno 11001] getaddrinfo failed

The above exception was the direct cause of the following exception:

Traceback (most recent call last):
  File "C:\Users\zcb16\AppData\Roaming\Python\Python312\site-packages\urllib3\connectionpool.py", line 787, in urlopen
    response = self._make_request(
               ^^^^^^^^^^^^^^^^^^^
  File "C:\Users\zcb16\AppData\Roaming\Python\Python312\site-packages\urllib3\connectionpool.py", line 488, in _make_request
    raise new_e
  File "C:\Users\zcb16\AppData\Roaming\Python\Python312\site-packages\urllib3\connectionpool.py", line 464, in _make_request
    self._validate_conn(conn)
  File "C:\Users\zcb16\AppData\Roaming\Python\Python312\site-packages\urllib3\connectionpool.py", line 1093, in _validate_conn
    conn.connect()
  File "C:\Users\zcb16\AppData\Roaming\Python\Python312\site-packages\urllib3\connection.py", line 753, in connect
    self.sock = sock = self._new_conn()
                       ^^^^^^^^^^^^^^^^
  File "C:\Users\zcb16\AppData\Roaming\Python\Python312\site-packages\urllib3\connection.py", line 205, in _new_conn
    raise NameResolutionError(self.host, self, e) from e
urllib3.exceptions.NameResolutionError: <urllib3.connection.HTTPSConnection object at 0x000001BDB50E5340>: Failed to resolve 'api.upbit.com' ([Errno 11001] getaddrinfo failed)

The above exception was the direct cause of the following exception:

Traceback (most recent call last):
  File "C:\Users\zcb16\AppData\Roaming\Python\Python312\site-packages\requests\adapters.py", line 667, in send
    resp = conn.urlopen(
           ^^^^^^^^^^^^^
  File "C:\Users\zcb16\AppData\Roaming\Python\Python312\site-packages\urllib3\connectionpool.py", line 841, in urlopen
    retries = retries.increment(
              ^^^^^^^^^^^^^^^^^^
  File "C:\Users\zcb16\AppData\Roaming\Python\Python312\site-packages\urllib3\util\retry.py", line 519, in increment
    raise MaxRetryError(_pool, url, reason) from reason  # type: ignore[arg-type]
    ^^^^^^^^^^^^^^^^^^^^^^^^^^^^^^^^^^^^^^^^^^^^^^^^^^^
urllib3.exceptions.MaxRetryError: HTTPSConnectionPool(host='api.upbit.com', port=443): Max retries exceeded with url: /v1/accounts (Caused by NameResolutionError("<urllib3.connection.HTTPSConnection object at 0x000001BDB50E5340>: Failed to resolve 'api.upbit.com' ([Errno 11001] getaddrinfo failed)"))

During handling of the above exception, another exception occurred:

Traceback (most recent call last):
  File "C:\Coding\AutoTrading\trading\portfolio.py", line 72, in get_comprehensive_investment_status
    break
       ^^^
  File "C:\Users\zcb16\AppData\Roaming\Python\Python312\site-packages\pyupbit\exchange_api.py", line 109, in get_balances
    result = _send_get_request(url, headers=headers)
             ^^^^^^^^^^^^^^^^^^^^^^^^^^^^^^^^^^^^^^^
  File "C:\Users\zcb16\AppData\Roaming\Python\Python312\site-packages\pyupbit\request_api.py", line 107, in _send_get_request
    resp = _call_get(url, headers=headers, data=data)
           ^^^^^^^^^^^^^^^^^^^^^^^^^^^^^^^^^^^^^^^^^^
  File "C:\Users\zcb16\AppData\Roaming\Python\Python312\site-packages\pyupbit\errors.py", line 165, in wrapper
    resp = func(*args, **kwargs)
           ^^^^^^^^^^^^^^^^^^^^^
  File "C:\Users\zcb16\AppData\Roaming\Python\Python312\site-packages\pyupbit\request_api.py", line 42, in _call_get
    return requests.get(url, **kwargs)
           ^^^^^^^^^^^^^^^^^^^^^^^^^^^
  File "C:\Users\zcb16\AppData\Roaming\Python\Python312\site-packages\requests\api.py", line 73, in get
    return request("get", url, params=params, **kwargs)
           ^^^^^^^^^^^^^^^^^^^^^^^^^^^^^^^^^^^^^^^^^^^^
  File "C:\Users\zcb16\AppData\Roaming\Python\Python312\site-packages\requests\api.py", line 59, in request
    return session.request(method=method, url=url, **kwargs)
           ^^^^^^^^^^^^^^^^^^^^^^^^^^^^^^^^^^^^^^^^^^^^^^^^^
  File "C:\Users\zcb16\AppData\Roaming\Python\Python312\site-packages\requests\sessions.py", line 589, in request
    resp = self.send(prep, **send_kwargs)
           ^^^^^^^^^^^^^^^^^^^^^^^^^^^^^^
  File "C:\Users\zcb16\AppData\Roaming\Python\Python312\site-packages\requests\sessions.py", line 703, in send
    r = adapter.send(request, **kwargs)
        ^^^^^^^^^^^^^^^^^^^^^^^^^^^^^^^
  File "C:\Users\zcb16\AppData\Roaming\Python\Python312\site-packages\requests\adapters.py", line 700, in send
    raise ConnectionError(e, request=request)
requests.exceptions.ConnectionError: HTTPSConnectionPool(host='api.upbit.com', port=443): Max retries exceeded with url: /v1/accounts (Caused by NameResolutionError("<urllib3.connection.HTTPSConnection object at 0x000001BDB50E5340>: Failed to resolve 'api.upbit.com' ([Errno 11001] getaddrinfo failed)"))

[2025-07-28 04:36:10] Failed to get comprehensive investment status.
[2025-07-28 04:36:10] [DEBUG] Investment status was None or empty.
[2025-07-28 04:36:40] 종합 투자 상태 조회 오류: HTTPSConnectionPool(host='api.upbit.com', port=443): Max retries exceeded with url: /v1/accounts (Caused by NameResolutionError("<urllib3.connection.HTTPSConnection object at 0x000001BDB50A7770>: Failed to resolve 'api.upbit.com' ([Errno 11001] getaddrinfo failed)"))
Traceback (most recent call last):
  File "C:\Users\zcb16\AppData\Roaming\Python\Python312\site-packages\urllib3\connection.py", line 198, in _new_conn
    sock = connection.create_connection(
           ^^^^^^^^^^^^^^^^^^^^^^^^^^^^^
  File "C:\Users\zcb16\AppData\Roaming\Python\Python312\site-packages\urllib3\util\connection.py", line 60, in create_connection
    for res in socket.getaddrinfo(host, port, family, socket.SOCK_STREAM):
               ^^^^^^^^^^^^^^^^^^^^^^^^^^^^^^^^^^^^^^^^^^^^^^^^^^^^^^^^^^
  File "C:\Python312\Lib\socket.py", line 976, in getaddrinfo
    for res in _socket.getaddrinfo(host, port, family, type, proto, flags):
               ^^^^^^^^^^^^^^^^^^^^^^^^^^^^^^^^^^^^^^^^^^^^^^^^^^^^^^^^^^^
socket.gaierror: [Errno 11001] getaddrinfo failed

The above exception was the direct cause of the following exception:

Traceback (most recent call last):
  File "C:\Users\zcb16\AppData\Roaming\Python\Python312\site-packages\urllib3\connectionpool.py", line 787, in urlopen
    response = self._make_request(
               ^^^^^^^^^^^^^^^^^^^
  File "C:\Users\zcb16\AppData\Roaming\Python\Python312\site-packages\urllib3\connectionpool.py", line 488, in _make_request
    raise new_e
  File "C:\Users\zcb16\AppData\Roaming\Python\Python312\site-packages\urllib3\connectionpool.py", line 464, in _make_request
    self._validate_conn(conn)
  File "C:\Users\zcb16\AppData\Roaming\Python\Python312\site-packages\urllib3\connectionpool.py", line 1093, in _validate_conn
    conn.connect()
  File "C:\Users\zcb16\AppData\Roaming\Python\Python312\site-packages\urllib3\connection.py", line 753, in connect
    self.sock = sock = self._new_conn()
                       ^^^^^^^^^^^^^^^^
  File "C:\Users\zcb16\AppData\Roaming\Python\Python312\site-packages\urllib3\connection.py", line 205, in _new_conn
    raise NameResolutionError(self.host, self, e) from e
urllib3.exceptions.NameResolutionError: <urllib3.connection.HTTPSConnection object at 0x000001BDB50A7770>: Failed to resolve 'api.upbit.com' ([Errno 11001] getaddrinfo failed)

The above exception was the direct cause of the following exception:

Traceback (most recent call last):
  File "C:\Users\zcb16\AppData\Roaming\Python\Python312\site-packages\requests\adapters.py", line 667, in send
    resp = conn.urlopen(
           ^^^^^^^^^^^^^
  File "C:\Users\zcb16\AppData\Roaming\Python\Python312\site-packages\urllib3\connectionpool.py", line 841, in urlopen
    retries = retries.increment(
              ^^^^^^^^^^^^^^^^^^
  File "C:\Users\zcb16\AppData\Roaming\Python\Python312\site-packages\urllib3\util\retry.py", line 519, in increment
    raise MaxRetryError(_pool, url, reason) from reason  # type: ignore[arg-type]
    ^^^^^^^^^^^^^^^^^^^^^^^^^^^^^^^^^^^^^^^^^^^^^^^^^^^
urllib3.exceptions.MaxRetryError: HTTPSConnectionPool(host='api.upbit.com', port=443): Max retries exceeded with url: /v1/accounts (Caused by NameResolutionError("<urllib3.connection.HTTPSConnection object at 0x000001BDB50A7770>: Failed to resolve 'api.upbit.com' ([Errno 11001] getaddrinfo failed)"))

During handling of the above exception, another exception occurred:

Traceback (most recent call last):
  File "C:\Coding\AutoTrading\trading\portfolio.py", line 72, in get_comprehensive_investment_status
    break
       ^^^
  File "C:\Users\zcb16\AppData\Roaming\Python\Python312\site-packages\pyupbit\exchange_api.py", line 109, in get_balances
    result = _send_get_request(url, headers=headers)
             ^^^^^^^^^^^^^^^^^^^^^^^^^^^^^^^^^^^^^^^
  File "C:\Users\zcb16\AppData\Roaming\Python\Python312\site-packages\pyupbit\request_api.py", line 107, in _send_get_request
    resp = _call_get(url, headers=headers, data=data)
           ^^^^^^^^^^^^^^^^^^^^^^^^^^^^^^^^^^^^^^^^^^
  File "C:\Users\zcb16\AppData\Roaming\Python\Python312\site-packages\pyupbit\errors.py", line 165, in wrapper
    resp = func(*args, **kwargs)
           ^^^^^^^^^^^^^^^^^^^^^
  File "C:\Users\zcb16\AppData\Roaming\Python\Python312\site-packages\pyupbit\request_api.py", line 42, in _call_get
    return requests.get(url, **kwargs)
           ^^^^^^^^^^^^^^^^^^^^^^^^^^^
  File "C:\Users\zcb16\AppData\Roaming\Python\Python312\site-packages\requests\api.py", line 73, in get
    return request("get", url, params=params, **kwargs)
           ^^^^^^^^^^^^^^^^^^^^^^^^^^^^^^^^^^^^^^^^^^^^
  File "C:\Users\zcb16\AppData\Roaming\Python\Python312\site-packages\requests\api.py", line 59, in request
    return session.request(method=method, url=url, **kwargs)
           ^^^^^^^^^^^^^^^^^^^^^^^^^^^^^^^^^^^^^^^^^^^^^^^^^
  File "C:\Users\zcb16\AppData\Roaming\Python\Python312\site-packages\requests\sessions.py", line 589, in request
    resp = self.send(prep, **send_kwargs)
           ^^^^^^^^^^^^^^^^^^^^^^^^^^^^^^
  File "C:\Users\zcb16\AppData\Roaming\Python\Python312\site-packages\requests\sessions.py", line 703, in send
    r = adapter.send(request, **kwargs)
        ^^^^^^^^^^^^^^^^^^^^^^^^^^^^^^^
  File "C:\Users\zcb16\AppData\Roaming\Python\Python312\site-packages\requests\adapters.py", line 700, in send
    raise ConnectionError(e, request=request)
requests.exceptions.ConnectionError: HTTPSConnectionPool(host='api.upbit.com', port=443): Max retries exceeded with url: /v1/accounts (Caused by NameResolutionError("<urllib3.connection.HTTPSConnection object at 0x000001BDB50A7770>: Failed to resolve 'api.upbit.com' ([Errno 11001] getaddrinfo failed)"))

[2025-07-28 04:36:40] Failed to get comprehensive investment status.
[2025-07-28 04:36:40] [DEBUG] Investment status was None or empty.
[2025-07-29 03:07:43] Failed to get comprehensive investment status.
[2025-07-29 03:07:43] [DEBUG] Investment status was None or empty.
[2025-07-29 10:38:24] Failed to get comprehensive investment status.
[2025-07-29 10:38:24] [DEBUG] Investment status was None or empty.
[2025-07-29 10:48:44] Error in AI full auto cycle: [Errno 22] Invalid argument
[2025-07-29 10:49:14] Failed to get comprehensive investment status.
[2025-07-29 10:49:14] [DEBUG] Investment status was None or empty.
[2025-07-29 10:49:47] Failed to get comprehensive investment status.
[2025-07-29 10:49:47] [DEBUG] Investment status was None or empty.
[2025-07-29 10:50:17] Failed to get comprehensive investment status.
[2025-07-29 10:50:17] [DEBUG] Investment status was None or empty.
[2025-07-29 10:50:47] Failed to get comprehensive investment status.
[2025-07-29 10:50:47] [DEBUG] Investment status was None or empty.
[2025-07-29 10:50:47] A critical error occurred in the main loop: [Errno 22] Invalid argument
